{
 "cells": [
  {
   "cell_type": "code",
   "execution_count": 20,
   "metadata": {},
   "outputs": [],
   "source": [
    "import tensorflow as tf\n",
    "\n",
    "import numpy as np\n",
    "\n",
    "from sklearn.preprocessing import MaxAbsScaler\n",
    "from sklearn.model_selection import train_test_split\n",
    "\n",
    "\n",
    "\n",
    "from tensorflow.keras.layers import Dense, Flatten, Dropout\n",
    "from tensorflow.keras import Model,losses\n",
    "\n",
    "import pandas as pd\n",
    "import os "
   ]
  },
  {
   "cell_type": "code",
   "execution_count": 8,
   "metadata": {},
   "outputs": [],
   "source": [
    "#INPUT\n",
    "input = 'HT001-FE002'\n",
    "fe = input.split(\"-\")[1]\n",
    "#EXPERIMENTO\n",
    "experimento = 'EN-003'\n",
    "\n",
    "#CARGO DATASETS\n",
    "os.chdir(\"C:/Users/vyago/Desktop/Yago/Competencia/ypf\")  # Directorio actual\n",
    "train = pd.read_csv(f\"../Exp/{fe}/train.csv\")\n",
    "test = pd.read_csv(f\"../Exp/{fe}/test.csv\")"
   ]
  },
  {
   "cell_type": "code",
   "execution_count": 9,
   "metadata": {},
   "outputs": [
    {
     "name": "stderr",
     "output_type": "stream",
     "text": [
      "c:\\Users\\vyago\\AppData\\Local\\Programs\\Python\\Python310\\lib\\site-packages\\pandas\\core\\arraylike.py:397: RuntimeWarning: invalid value encountered in sqrt\n",
      "  result = getattr(ufunc, method)(*inputs, **kwargs)\n"
     ]
    }
   ],
   "source": [
    "train = train.select_dtypes(\"number\")\n",
    "y_train = np.sqrt(train[\"delta_WHP\"])\n",
    "train = train[train.columns.drop([\"delta_WHP\",\"ID_FILA\"])]"
   ]
  },
  {
   "cell_type": "code",
   "execution_count": 10,
   "metadata": {},
   "outputs": [],
   "source": [
    "#ESTANDARIZO FEATURES\n",
    "\n",
    "transformer = MaxAbsScaler().fit(train)\n",
    "X_train= transformer.transform(train)\n",
    "\n"
   ]
  },
  {
   "cell_type": "code",
   "execution_count": 27,
   "metadata": {},
   "outputs": [
    {
     "data": {
      "text/plain": [
       "(26178, 31)"
      ]
     },
     "execution_count": 27,
     "metadata": {},
     "output_type": "execute_result"
    }
   ],
   "source": [
    "X_train.shape"
   ]
  },
  {
   "cell_type": "code",
   "execution_count": 34,
   "metadata": {},
   "outputs": [],
   "source": [
    "#MODELO \n",
    "\n",
    "modelo = tf.keras.models.Sequential([\n",
    "  tf.keras.layers.Flatten(),\n",
    "  tf.keras.layers.Dense(128, activation='relu'),\n",
    "  tf.keras.layers.Dropout(0.6),\n",
    "  tf.keras.layers.Dense(128, activation='relu'),\n",
    "  tf.keras.layers.Dropout(0.6),\n",
    "  tf.keras.layers.Dense(32, activation='relu'),\n",
    "  tf.keras.layers.Dense(1,activation=\"linear\")\n",
    "])\n",
    "\n"
   ]
  },
  {
   "cell_type": "code",
   "execution_count": 36,
   "metadata": {},
   "outputs": [
    {
     "name": "stdout",
     "output_type": "stream",
     "text": [
      "Epoch 1/1000\n"
     ]
    },
    {
     "ename": "ValueError",
     "evalue": "in user code:\n\n    File \"c:\\Users\\vyago\\AppData\\Local\\Programs\\Python\\Python310\\lib\\site-packages\\keras\\engine\\training.py\", line 1160, in train_function  *\n        return step_function(self, iterator)\n    File \"c:\\Users\\vyago\\AppData\\Local\\Programs\\Python\\Python310\\lib\\site-packages\\keras\\engine\\training.py\", line 1146, in step_function  **\n        outputs = model.distribute_strategy.run(run_step, args=(data,))\n    File \"c:\\Users\\vyago\\AppData\\Local\\Programs\\Python\\Python310\\lib\\site-packages\\keras\\engine\\training.py\", line 1135, in run_step  **\n        outputs = model.train_step(data)\n    File \"c:\\Users\\vyago\\AppData\\Local\\Programs\\Python\\Python310\\lib\\site-packages\\keras\\engine\\training.py\", line 994, in train_step\n        loss = self.compute_loss(x, y, y_pred, sample_weight)\n    File \"c:\\Users\\vyago\\AppData\\Local\\Programs\\Python\\Python310\\lib\\site-packages\\keras\\engine\\training.py\", line 1052, in compute_loss\n        return self.compiled_loss(\n    File \"c:\\Users\\vyago\\AppData\\Local\\Programs\\Python\\Python310\\lib\\site-packages\\keras\\engine\\compile_utils.py\", line 240, in __call__\n        self.build(y_pred)\n    File \"c:\\Users\\vyago\\AppData\\Local\\Programs\\Python\\Python310\\lib\\site-packages\\keras\\engine\\compile_utils.py\", line 182, in build\n        self._losses = tf.nest.map_structure(\n    File \"c:\\Users\\vyago\\AppData\\Local\\Programs\\Python\\Python310\\lib\\site-packages\\keras\\engine\\compile_utils.py\", line 353, in _get_loss_object\n        loss = losses_mod.get(loss)\n    File \"c:\\Users\\vyago\\AppData\\Local\\Programs\\Python\\Python310\\lib\\site-packages\\keras\\losses.py\", line 2649, in get\n        return deserialize(identifier)\n    File \"c:\\Users\\vyago\\AppData\\Local\\Programs\\Python\\Python310\\lib\\site-packages\\keras\\losses.py\", line 2603, in deserialize\n        return deserialize_keras_object(\n    File \"c:\\Users\\vyago\\AppData\\Local\\Programs\\Python\\Python310\\lib\\site-packages\\keras\\utils\\generic_utils.py\", line 769, in deserialize_keras_object\n        raise ValueError(\n\n    ValueError: Unknown loss function: mean-absolute-error. Please ensure this object is passed to the `custom_objects` argument. See https://www.tensorflow.org/guide/keras/save_and_serialize#registering_the_custom_object for details.\n",
     "output_type": "error",
     "traceback": [
      "\u001b[1;31m---------------------------------------------------------------------------\u001b[0m",
      "\u001b[1;31mValueError\u001b[0m                                Traceback (most recent call last)",
      "\u001b[1;32mc:\\Users\\vyago\\Desktop\\Yago\\Competencia\\ypf\\src\\NeuralNetworks\\nn_simple.ipynb Celda 7\u001b[0m in \u001b[0;36m<cell line: 3>\u001b[1;34m()\u001b[0m\n\u001b[0;32m      <a href='vscode-notebook-cell:/c%3A/Users/vyago/Desktop/Yago/Competencia/ypf/src/NeuralNetworks/nn_simple.ipynb#W5sZmlsZQ%3D%3D?line=0'>1</a>\u001b[0m modelo\u001b[39m.\u001b[39mcompile(optimizer\u001b[39m=\u001b[39m\u001b[39m'\u001b[39m\u001b[39madam\u001b[39m\u001b[39m'\u001b[39m, loss\u001b[39m=\u001b[39m\u001b[39m'\u001b[39m\u001b[39mmean-absolute-error\u001b[39m\u001b[39m'\u001b[39m,metrics\u001b[39m=\u001b[39mtf\u001b[39m.\u001b[39mkeras\u001b[39m.\u001b[39mmetrics\u001b[39m.\u001b[39mRootMeanSquaredError())\n\u001b[1;32m----> <a href='vscode-notebook-cell:/c%3A/Users/vyago/Desktop/Yago/Competencia/ypf/src/NeuralNetworks/nn_simple.ipynb#W5sZmlsZQ%3D%3D?line=2'>3</a>\u001b[0m modelo\u001b[39m.\u001b[39;49mfit(x\u001b[39m=\u001b[39;49mX_train,y\u001b[39m=\u001b[39;49my_train,batch_size\u001b[39m=\u001b[39;49m\u001b[39m256\u001b[39;49m,epochs\u001b[39m=\u001b[39;49m\u001b[39m1000\u001b[39;49m)\n",
      "File \u001b[1;32mc:\\Users\\vyago\\AppData\\Local\\Programs\\Python\\Python310\\lib\\site-packages\\keras\\utils\\traceback_utils.py:70\u001b[0m, in \u001b[0;36mfilter_traceback.<locals>.error_handler\u001b[1;34m(*args, **kwargs)\u001b[0m\n\u001b[0;32m     67\u001b[0m     filtered_tb \u001b[39m=\u001b[39m _process_traceback_frames(e\u001b[39m.\u001b[39m__traceback__)\n\u001b[0;32m     68\u001b[0m     \u001b[39m# To get the full stack trace, call:\u001b[39;00m\n\u001b[0;32m     69\u001b[0m     \u001b[39m# `tf.debugging.disable_traceback_filtering()`\u001b[39;00m\n\u001b[1;32m---> 70\u001b[0m     \u001b[39mraise\u001b[39;00m e\u001b[39m.\u001b[39mwith_traceback(filtered_tb) \u001b[39mfrom\u001b[39;00m \u001b[39mNone\u001b[39m\n\u001b[0;32m     71\u001b[0m \u001b[39mfinally\u001b[39;00m:\n\u001b[0;32m     72\u001b[0m     \u001b[39mdel\u001b[39;00m filtered_tb\n",
      "File \u001b[1;32m~\\AppData\\Local\\Temp\\__autograph_generated_file34a0v4ky.py:15\u001b[0m, in \u001b[0;36mouter_factory.<locals>.inner_factory.<locals>.tf__train_function\u001b[1;34m(iterator)\u001b[0m\n\u001b[0;32m     13\u001b[0m \u001b[39mtry\u001b[39;00m:\n\u001b[0;32m     14\u001b[0m     do_return \u001b[39m=\u001b[39m \u001b[39mTrue\u001b[39;00m\n\u001b[1;32m---> 15\u001b[0m     retval_ \u001b[39m=\u001b[39m ag__\u001b[39m.\u001b[39mconverted_call(ag__\u001b[39m.\u001b[39mld(step_function), (ag__\u001b[39m.\u001b[39mld(\u001b[39mself\u001b[39m), ag__\u001b[39m.\u001b[39mld(iterator)), \u001b[39mNone\u001b[39;00m, fscope)\n\u001b[0;32m     16\u001b[0m \u001b[39mexcept\u001b[39;00m:\n\u001b[0;32m     17\u001b[0m     do_return \u001b[39m=\u001b[39m \u001b[39mFalse\u001b[39;00m\n",
      "\u001b[1;31mValueError\u001b[0m: in user code:\n\n    File \"c:\\Users\\vyago\\AppData\\Local\\Programs\\Python\\Python310\\lib\\site-packages\\keras\\engine\\training.py\", line 1160, in train_function  *\n        return step_function(self, iterator)\n    File \"c:\\Users\\vyago\\AppData\\Local\\Programs\\Python\\Python310\\lib\\site-packages\\keras\\engine\\training.py\", line 1146, in step_function  **\n        outputs = model.distribute_strategy.run(run_step, args=(data,))\n    File \"c:\\Users\\vyago\\AppData\\Local\\Programs\\Python\\Python310\\lib\\site-packages\\keras\\engine\\training.py\", line 1135, in run_step  **\n        outputs = model.train_step(data)\n    File \"c:\\Users\\vyago\\AppData\\Local\\Programs\\Python\\Python310\\lib\\site-packages\\keras\\engine\\training.py\", line 994, in train_step\n        loss = self.compute_loss(x, y, y_pred, sample_weight)\n    File \"c:\\Users\\vyago\\AppData\\Local\\Programs\\Python\\Python310\\lib\\site-packages\\keras\\engine\\training.py\", line 1052, in compute_loss\n        return self.compiled_loss(\n    File \"c:\\Users\\vyago\\AppData\\Local\\Programs\\Python\\Python310\\lib\\site-packages\\keras\\engine\\compile_utils.py\", line 240, in __call__\n        self.build(y_pred)\n    File \"c:\\Users\\vyago\\AppData\\Local\\Programs\\Python\\Python310\\lib\\site-packages\\keras\\engine\\compile_utils.py\", line 182, in build\n        self._losses = tf.nest.map_structure(\n    File \"c:\\Users\\vyago\\AppData\\Local\\Programs\\Python\\Python310\\lib\\site-packages\\keras\\engine\\compile_utils.py\", line 353, in _get_loss_object\n        loss = losses_mod.get(loss)\n    File \"c:\\Users\\vyago\\AppData\\Local\\Programs\\Python\\Python310\\lib\\site-packages\\keras\\losses.py\", line 2649, in get\n        return deserialize(identifier)\n    File \"c:\\Users\\vyago\\AppData\\Local\\Programs\\Python\\Python310\\lib\\site-packages\\keras\\losses.py\", line 2603, in deserialize\n        return deserialize_keras_object(\n    File \"c:\\Users\\vyago\\AppData\\Local\\Programs\\Python\\Python310\\lib\\site-packages\\keras\\utils\\generic_utils.py\", line 769, in deserialize_keras_object\n        raise ValueError(\n\n    ValueError: Unknown loss function: mean-absolute-error. Please ensure this object is passed to the `custom_objects` argument. See https://www.tensorflow.org/guide/keras/save_and_serialize#registering_the_custom_object for details.\n"
     ]
    }
   ],
   "source": [
    "\n",
    "modelo.compile(optimizer='adam', loss='mean-absolute-error',metrics=tf.keras.metrics.RootMeanSquaredError())\n",
    "\n",
    "modelo.fit(x=X_train,y=y_train,batch_size=256,epochs=1000)\n"
   ]
  },
  {
   "cell_type": "code",
   "execution_count": null,
   "metadata": {},
   "outputs": [],
   "source": []
  }
 ],
 "metadata": {
  "kernelspec": {
   "display_name": "Python 3.10.6 64-bit",
   "language": "python",
   "name": "python3"
  },
  "language_info": {
   "codemirror_mode": {
    "name": "ipython",
    "version": 3
   },
   "file_extension": ".py",
   "mimetype": "text/x-python",
   "name": "python",
   "nbconvert_exporter": "python",
   "pygments_lexer": "ipython3",
   "version": "3.10.6"
  },
  "orig_nbformat": 4,
  "vscode": {
   "interpreter": {
    "hash": "8d832290213029041eddbbc4b8a0a553d5df210b193f32fda00218f7fc512b12"
   }
  }
 },
 "nbformat": 4,
 "nbformat_minor": 2
}
